Workbook

Sheet Financials>

Sheet Historical FS
B2: ="Historical Financial Statement - "&'Data Sheet'!B1 -> Historical Financial Statement - ITC LTD
B3: Years | C3: ='Data Sheet'!B16 -> 42460 | D3: ='Data Sheet'!C16 -> 42825 | E3: ='Data Sheet'!D16 -> 43190 | F3: ='Data Sheet'!E16 -> 43555 | G3: ='Data Sheet'!F16 -> 43921 | H3: ='Data Sheet'!G16 -> 44286 | I3: ='Data Sheet'!H16 -> 44651 | J3: ='Data Sheet'!I16 -> 45016 | ... L3: ='Data Sheet'!K16 -> 45747 | M3: LTM
A5: # | B5: Income Statement
B6: Sales | C6: =IFERROR('Data Sheet'!B17,0) -> 39192.1 | D6: =IFERROR('Data Sheet'!C17,0) -> 42767.6 | E6: =IFERROR('Data Sheet'!D17,0) -> 43448.94 | F6: =IFERROR('Data Sheet'!E17,0) -> 48339.58 | G6: =IFERROR('Data Sheet'!F17,0) -> 49387.7 | H6: =IFERROR('Data Sheet'!G17,0) -> 49257.45 | I6: =IFERROR('Data Sheet'!H17,0) -> 60644.54 | J6: =IFERROR('Data Sheet'!I17,0) -> 70919.03 | ... L6: =IFERROR('Data Sheet'!K17,0) -> 75323.34 | M6: =IFERROR(SUM('Data Sheet'!H42:K42),0) -> 79808.72
B7: Sales Growth | C7: - | D7: =D6/C6-1 -> 0.09123012 | E7: =E6/D6-1 -> 0.015931219 | F7: =F6/E6-1 -> 0.11256063 | G7: =G6/F6-1 -> 0.021682439 | H7: =H6/G6-1 -> -0.0026372963 | I7: =I6/H6-1 -> 0.23117498 | J7: =J6/I6-1 -> 0.16942152 | K7: =K6/J6-1 -> -0.042119724 | ... M7: =M6/L6-1 -> 0.059548342
B9: COGS | C9: =IFERROR(SUM('Data Sheet'!B18,'Data Sheet'!B20:B22)-1*'Data Sheet'!B19,0) -> 19162.94 | D9: =IFERROR(SUM('Data Sheet'!C18,'Data Sheet'!C20:C22)-1*'Data Sheet'!C19,0) -> 21949.12 | E9: =IFERROR(SUM('Data Sheet'!D18,'Data Sheet'!D20:D22)-1*'Data Sheet'!D19,0) -> 21967.5 | F9: =IFERROR(SUM('Data Sheet'!E18,'Data Sheet'!E20:E22)-1*'Data Sheet'!E19,0) -> 24215.95 | G9: =IFERROR(SUM('Data Sheet'!F18,'Data Sheet'!F20:F22)-1*'Data Sheet'!F19,0) -> 24330.4 | H9: =IFERROR(SUM('Data Sheet'!G18,'Data Sheet'!G20:G22)-1*'Data Sheet'!G19,0) -> 26881.51 | I9: =IFERROR(SUM('Data Sheet'!H18,'Data Sheet'!H20:H22)-1*'Data Sheet'!H19,0) -> 34053.06 | J9: =IFERROR(SUM('Data Sheet'!I18,'Data Sheet'!I20:I22)-1*'Data Sheet'!I19,0) -> 38302.13 | ... L9: =IFERROR(SUM('Data Sheet'!K18,'Data Sheet'!K20:K22)-1*'Data Sheet'!K19,0) -> 41469.21 | M9: =IFERROR(SUM('Data Sheet'!H43:K43),0) -> 52895.65
B10: COGS % Sales | C10: =C9/C6 -> 0.48894905 | D10: =D9/D6 -> 0.51321842 | E10: =E9/E6 -> 0.50559346 | F10: =F9/F6 -> 0.50095491 | G10: =G9/G6 -> 0.49264088 | H10: =H9/H6 -> 0.54573491 | I10: =I9/I6 -> 0.56151898 | J10: =J9/J6 -> 0.54008254 | ... M10: =M9/M6 -> 0.66278033
B12: Gross Profit | C12: =C6-C9 -> 20029.16 | D12: =D6-D9 -> 20818.48 | E12: =E6-E9 -> 21481.44 | F12: =F6-F9 -> 24123.63 | G12: =G6-G9 -> 25057.3 | H12: =H6-H9 -> 22375.94 | I12: =I6-I9 -> 26591.48 | J12: =J6-J9 -> 32616.9 | ... M12: =M6-M9 -> 26913.07
B13: Gross Margins | C13: =C12/C6 -> 0.51105095 | D13: =D12/D6 -> 0.48678158 | E13: =E12/E6 -> 0.49440654 | F13: =F12/F6 -> 0.49904509 | G13: =G12/G6 -> 0.50735912 | H13: =H12/H6 -> 0.45426509 | I13: =I12/I6 -> 0.43848102 | J13: =J12/J6 -> 0.45991746 | ... M13: =M12/M6 -> 0.33721967
B15: Selling & General Expenses | C15: =IFERROR(SUM('Data Sheet'!B23:B24),0) -> 5497.67 | D15: =IFERROR(SUM('Data Sheet'!C23:C24),0) -> 5348.97 | E15: =IFERROR(SUM('Data Sheet'!D23:D24),0) -> 4960.85 | F15: =IFERROR(SUM('Data Sheet'!E23:E24),0) -> 5586.24 | G15: =IFERROR(SUM('Data Sheet'!F23:F24),0) -> 5713.76 | H15: =IFERROR(SUM('Data Sheet'!G23:G24),0) -> 5311.16 | I15: =IFERROR(SUM('Data Sheet'!H23:H24),0) -> 5968.33 | J15: =IFERROR(SUM('Data Sheet'!I23:I24),0) -> 6912.64 | ... M15: =IFERROR(SUM('Data Sheet'!L23:L24),0) -> 0
B16: S&G Expenses % Sales | C16: =C15/C6 -> 0.14027495 | D16: =D15/D6 -> 0.12507061 | E16: =E15/E6 -> 0.11417655 | F16: =F15/F6 -> 0.11556244 | G16: =G15/G6 -> 0.11569196 | H16: =H15/H6 -> 0.1078245 | I16: =I15/I6 -> 0.09841496 | J16: =J15/J6 -> 0.097472286 | ... M16: =M15/M6 -> 0
B18: EBITDA | C18: =C12-C15 -> 14531.49 | D18: =D12-D15 -> 15469.51 | E18: =E12-E15 -> 16520.59 | F18: =F12-F15 -> 18537.39 | G18: =G12-G15 -> 19343.54 | H18: =H12-H15 -> 17064.78 | I18: =I12-I15 -> 20623.15 | J18: =J12-J15 -> 25704.26 | ... L18: =L12-L15 -> 25839.45
B19: EBITDA Margins | C19: =C18/C6 -> 0.370776 | D19: =D18/D6 -> 0.36171097 | E19: =E18/E6 -> 0.38022999 | F19: =F18/F6 -> 0.38348265 | G19: =G18/G6 -> 0.39166716 | H19: =H18/H6 -> 0.34644059 | I19: =I18/I6 -> 0.34006606 | J19: =J18/J6 -> 0.36244517 | ... M19: =M18/M6 -> 0
B21: Interest | C21: =IFERROR('Data Sheet'!B27,0) -> 78.13 | D21: =IFERROR('Data Sheet'!C27,0) -> 49.03 | E21: =IFERROR('Data Sheet'!D27,0) -> 115.01 | F21: =IFERROR('Data Sheet'!E27,0) -> 71.4 | G21: =IFERROR('Data Sheet'!F27,0) -> 81.38 | H21: =IFERROR('Data Sheet'!G27,0) -> 57.97 | I21: =IFERROR('Data Sheet'!H27,0) -> 59.99 | J21: =IFERROR('Data Sheet'!I27,0) -> 77.77 | ... L21: =IFERROR('Data Sheet'!K27,0) -> 45.06 | M21: =IFERROR(SUM('Data Sheet'!H46:K46),0) -> 66.9
B22: Interest % Sales | C22: =C21/C6 -> 0.001993514 | D22: =D21/D6 -> 0.0011464286 | E22: =E21/E6 -> 0.0026470151 | F22: =F21/F6 -> 0.0014770505 | G22: =G21/G6 -> 0.0016477787 | H22: =H21/H6 -> 0.0011768778 | I22: =I21/I6 -> 0.00098920694 | J22: =J21/J6 -> 0.0010966027 | ... M22: =M21/M6 -> 0.00083825427
B24: Depriciation | C24: =IFERROR('Data Sheet'!B26,0) -> 1077.4 | D24: =IFERROR('Data Sheet'!C26,0) -> 1152.79 | E24: =IFERROR('Data Sheet'!D26,0) -> 1236.28 | F24: =IFERROR('Data Sheet'!E26,0) -> 1396.61 | G24: =IFERROR('Data Sheet'!F26,0) -> 1644.91 | H24: =IFERROR('Data Sheet'!G26,0) -> 1645.59 | I24: =IFERROR('Data Sheet'!H26,0) -> 1732.41 | J24: =IFERROR('Data Sheet'!I26,0) -> 1809.01 | ... L24: =IFERROR('Data Sheet'!K26,0) -> 1646.32 | M24: =IFERROR(SUM('Data Sheet'!H45:K45),0) -> 1699.61
B25: Depriciation % Sales | C25: =C24/C6 -> 0.027490234 | D25: =D24/D6 -> 0.026954751 | E25: =E24/E6 -> 0.028453629 | F25: =F24/F6 -> 0.028891645 | G25: =G24/G6 -> 0.033306066 | H25: =H24/H6 -> 0.033407941 | I25: =I24/I6 -> 0.028566628 | J25: =J24/J6 -> 0.025508104 | ... M25: =M24/M6 -> 0.021296044
B27: Earnings Before Tax EBT | C27: =IFERROR(C18-SUM(C24,C21),0) -> 13375.96 | D27: =IFERROR(D18-SUM(D24,D21),0) -> 14267.69 | E27: =IFERROR(E18-SUM(E24,E21),0) -> 15169.3 | F27: =IFERROR(F18-SUM(F24,F21),0) -> 17069.38 | G27: =IFERROR(G18-SUM(G24,G21),0) -> 17617.25 | H27: =IFERROR(H18-SUM(H24,H21),0) -> 15361.22 | I27: =IFERROR(I18-SUM(I24,I21),0) -> 18830.75 | J27: =IFERROR(J18-SUM(J24,J21),0) -> 23817.48 | ... L27: =IFERROR(L18-SUM(L24,L21),0) -> 24148.07 | M27: =IFERROR(SUM('Data Sheet'!H47:K47),0) -> 42349.5
B28: EBT % Sales | C28: =C27/C6 -> 0.34129225 | D28: =D27/D6 -> 0.33360979 | E28: =E27/E6 -> 0.34912935 | F28: =F27/F6 -> 0.35311395 | G28: =G27/G6 -> 0.35671331 | H28: =H27/H6 -> 0.31185577 | I28: =I27/I6 -> 0.31051023 | J28: =J27/J6 -> 0.33584046 | ... M28: =M27/M6 -> 0.5306375
B30: Tax | C30: =IFERROR('Data Sheet'!B29,0) -> 5358.21 | D30: =IFERROR('Data Sheet'!C29,0) -> 5549.09 | E30: =IFERROR('Data Sheet'!D29,0) -> 5916.43 | F30: =IFERROR('Data Sheet'!E29,0) -> 6313.92 | G30: =IFERROR('Data Sheet'!F29,0) -> 4441.79 | H30: =IFERROR('Data Sheet'!G29,0) -> 4555.29 | I30: =IFERROR('Data Sheet'!H29,0) -> 5237.34 | J30: =IFERROR('Data Sheet'!I29,0) -> 6438.4 | ... L30: =IFERROR('Data Sheet'!K29,0) -> 6890.47 | M30: =IFERROR(SUM('Data Sheet'!H48:K48),0) -> 6993.21
B31: Effective Tax Rate | C31: =C30/C27 -> 0.40058508 | D31: =D30/D27 -> 0.38892701 | E31: =E30/E27 -> 0.39002657 | F31: =F30/F27 -> 0.36989744 | G31: =G30/G27 -> 0.25212732 | H31: =H30/H27 -> 0.29654481 | I31: =I30/I27 -> 0.278127 | J31: =J30/J27 -> 0.27032247 | ... M31: =M30/M27 -> 0.16513088
B33: Net Profit | C33: =IFERROR(C27-C30,0) -> 8017.75 | D33: =IFERROR(D27-D30,0) -> 8718.6 | E33: =IFERROR(E27-E30,0) -> 9252.87 | F33: =IFERROR(F27-F30,0) -> 10755.46 | G33: =IFERROR(G27-G30,0) -> 13175.46 | H33: =IFERROR(H27-H30,0) -> 10805.93 | I33: =IFERROR(I27-I30,0) -> 13593.41 | J33: =IFERROR(J27-J30,0) -> 17379.08 | ... L33: =IFERROR(L27-L30,0) -> 17257.6 | M33: =IFERROR(SUM('Data Sheet'!H49:K49),0) -> 35028.87
B34: Net Margins | C34: =C33/C6 -> 0.20457567 | D34: =D33/D6 -> 0.20385993 | E34: =E33/E6 -> 0.21295963 | F34: =F33/F6 -> 0.222498 | G34: =G33/G6 -> 0.26677614 | H34: =H33/H6 -> 0.21937656 | I34: =I33/I6 -> 0.22414895 | J34: =J33/J6 -> 0.24505524 | ... M34: =M33/M6 -> 0.43891031
B36: No. of Equity Shares | C36: =IFERROR('Data Sheet'!B93,0) -> 1207.08 | D36: =IFERROR('Data Sheet'!C93,0) -> 1214.74 | E36: =IFERROR('Data Sheet'!D93,0) -> 1220.43 | F36: =IFERROR('Data Sheet'!E93,0) -> 1225.86 | G36: =IFERROR('Data Sheet'!F93,0) -> 1229.22 | H36: =IFERROR('Data Sheet'!G93,0) -> 1230.88 | I36: =IFERROR('Data Sheet'!H93,0) -> 1232.33 | J36: =IFERROR('Data Sheet'!I93,0) -> 1242.8 | ... M36: =IFERROR('Data Sheet'!L93,0) -> 0
B38: Earning Per Share EPS | C38: =IFERROR(C33/C36,0) -> 6.6422689 | D38: =IFERROR(D33/D36,0) -> 7.1773384 | E38: =IFERROR(E33/E36,0) -> 7.5816475 | F38: =IFERROR(F33/F36,0) -> 8.7738078 | G38: =IFERROR(G33/G36,0) -> 10.718553 | H38: =IFERROR(H33/H36,0) -> 8.779028 | I38: =IFERROR(I33/I36,0) -> 11.030657 | J38: =IFERROR(J33/J36,0) -> 13.983811 | ... M38: =IFERROR(M33/M36,0) -> 0
B39: EPS Growth % | C39: =IFERROR(C38/B38-1,0) -> 0 | D39: =IFERROR(D38/C38-1,0) -> 0.080555217 | E39: =IFERROR(E38/D38-1,0) -> 0.056331341 | F39: =IFERROR(F38/E38-1,0) -> 0.15724291 | G39: =IFERROR(G38/F38-1,0) -> 0.22165353 | H39: =IFERROR(H38/G38-1,0) -> -0.18095028 | I39: =IFERROR(I38/H38-1,0) -> 0.25647821 | J39: =IFERROR(J38/I38-1,0) -> 0.26772234 | ... M39: =IFERROR(M38/L38-1,0) -> -1
B41: Dividend Per Share DPS | C41: =IFERROR('Data Sheet'!B31/'Historical FS'!C36,0) -> 5.6666667 | D41: =IFERROR('Data Sheet'!C31/'Historical FS'!D36,0) -> 4.7500041 | E41: =IFERROR('Data Sheet'!D31/'Historical FS'!E36,0) -> 5.1499963 | F41: =IFERROR('Data Sheet'!E31/'Historical FS'!F36,0) -> 5.7500041 | G41: =IFERROR('Data Sheet'!F31/'Historical FS'!G36,0) -> 10.149998 | H41: =IFERROR('Data Sheet'!G31/'Historical FS'!H36,0) -> 10.75 | I41: =IFERROR('Data Sheet'!H31/'Historical FS'!I36,0) -> 11.500004 | J41: =IFERROR('Data Sheet'!I31/'Historical FS'!J36,0) -> 15.5 | ... M41: =IFERROR('Data Sheet'!L31/'Historical FS'!M36,0) -> 0
B42: Dividend Payout Ratio | C42: =IFERROR(C41/C38,0) -> 0.85312214 | D42: =IFERROR(D41/D38,0) -> 0.66180579 | E42: =IFERROR(E41/E38,0) -> 0.6792714 | F42: =IFERROR(F41/F38,0) -> 0.65536016 | G42: =IFERROR(G41/G38,0) -> 0.94695593 | H42: =IFERROR(H41/H38,0) -> 1.2245091 | I42: =IFERROR(I41/I38,0) -> 1.0425493 | J42: =IFERROR(J41/J38,0) -> 1.1084246 | ... L42: =IFERROR(L41/L38,0) -> 1.0405694 | M42: -
B44: Retained Earnings | C44: =IFERROR(IF(C38>C41,1-C42,0),0) -> 0.14687786 | D44: =IFERROR(IF(D38>D41,1-D42,0),0) -> 0.33819421 | E44: =IFERROR(IF(E38>E41,1-E42,0),0) -> 0.3207286 | F44: =IFERROR(IF(F38>F41,1-F42,0),0) -> 0.34463984 | G44: =IFERROR(IF(G38>G41,1-G42,0),0) -> 0.053044068 | H44: =IFERROR(IF(H38>H41,1-H42,0),0) -> 0 | I44: =IFERROR(IF(I38>I41,1-I42,0),0) -> 0 | J44: =IFERROR(IF(J38>J41,1-J42,0),0) -> 0 | ... M44: =IFERROR(IF(M38>M41,1-M42,0),0) -> 0
A46: # | B46: Balance Sheet
B47: Equity Share Capital | C47: =IFERROR('Data Sheet'!B57,0) -> 804.72 | D47: =IFERROR('Data Sheet'!C57,0) -> 1214.74 | E47: =IFERROR('Data Sheet'!D57,0) -> 1220.43 | F47: =IFERROR('Data Sheet'!E57,0) -> 1225.86 | G47: =IFERROR('Data Sheet'!F57,0) -> 1229.22 | H47: =IFERROR('Data Sheet'!G57,0) -> 1230.88 | I47: =IFERROR('Data Sheet'!H57,0) -> 1232.33 | J47: =IFERROR('Data Sheet'!I57,0) -> 1242.8 | ... L47: =IFERROR('Data Sheet'!K57,0) -> 1251.41
B48: Reserves | C48: =IFERROR('Data Sheet'!B58,0) -> 41874.8 | D48: =IFERROR('Data Sheet'!C58,0) -> 45198.19 | E48: =IFERROR('Data Sheet'!D58,0) -> 51289.68 | F48: =IFERROR('Data Sheet'!E58,0) -> 57915.01 | G48: =IFERROR('Data Sheet'!F58,0) -> 64044.04 | H48: =IFERROR('Data Sheet'!G58,0) -> 59116.46 | I48: =IFERROR('Data Sheet'!H58,0) -> 61223.24 | J48: =IFERROR('Data Sheet'!I58,0) -> 67912.46 | ... L48: =IFERROR('Data Sheet'!K58,0) -> 68778.64
B49: Borrowings | C49: =IFERROR('Data Sheet'!B59,0) -> 83.78 | D49: =IFERROR('Data Sheet'!C59,0) -> 45.72 | E49: =IFERROR('Data Sheet'!D59,0) -> 35.92 | F49: =IFERROR('Data Sheet'!E59,0) -> 13.44 | G49: =IFERROR('Data Sheet'!F59,0) -> 277.45 | H49: =IFERROR('Data Sheet'!G59,0) -> 270.83 | I49: =IFERROR('Data Sheet'!H59,0) -> 249.44 | J49: =IFERROR('Data Sheet'!I59,0) -> 306.04 | ... L49: =IFERROR('Data Sheet'!K59,0) -> 284.54
B50: Other Liabilities | C50: =IFERROR('Data Sheet'!B60,0) -> 8888.04 | D50: =IFERROR('Data Sheet'!C60,0) -> 9439.67 | E50: =IFERROR('Data Sheet'!D60,0) -> 11694.85 | F50: =IFERROR('Data Sheet'!E60,0) -> 12584.73 | G50: =IFERROR('Data Sheet'!F60,0) -> 11760.04 | H50: =IFERROR('Data Sheet'!G60,0) -> 13142.59 | I50: =IFERROR('Data Sheet'!H60,0) -> 14491.01 | J50: =IFERROR('Data Sheet'!I60,0) -> 16369.66 | ... L50: =IFERROR('Data Sheet'!K60,0) -> 17688.11
B51: Total Liabilities | C51: =IFERROR('Data Sheet'!B61,0) -> 51651.34 | D51: =IFERROR('Data Sheet'!C61,0) -> 55898.32 | E51: =IFERROR('Data Sheet'!D61,0) -> 64240.88 | F51: =IFERROR('Data Sheet'!E61,0) -> 71739.04 | G51: =IFERROR('Data Sheet'!F61,0) -> 77310.75 | H51: =IFERROR('Data Sheet'!G61,0) -> 73760.76 | I51: =IFERROR('Data Sheet'!H61,0) -> 77196.02 | J51: =IFERROR('Data Sheet'!I61,0) -> 85830.96 | ... L51: =IFERROR('Data Sheet'!K61,0) -> 88002.7
B53: Fixed Assests Net Block | C53: =IFERROR('Data Sheet'!B62,0) -> 15106.63 | D53: =IFERROR('Data Sheet'!C62,0) -> 15893.48 | E53: =IFERROR('Data Sheet'!D62,0) -> 16523.96 | F53: =IFERROR('Data Sheet'!E62,0) -> 19374.19 | G53: =IFERROR('Data Sheet'!F62,0) -> 21713.34 | H53: =IFERROR('Data Sheet'!G62,0) -> 23298.48 | I53: =IFERROR('Data Sheet'!H62,0) -> 24231.59 | J53: =IFERROR('Data Sheet'!I62,0) -> 25851.27 | ... L53: =IFERROR('Data Sheet'!K62,0) -> 21954.85
B54: Capital Work in Progress | C54: =IFERROR('Data Sheet'!B63,0) -> 2559.72 | D54: =IFERROR('Data Sheet'!C63,0) -> 3729.89 | E54: =IFERROR('Data Sheet'!D63,0) -> 5508.33 | F54: =IFERROR('Data Sheet'!E63,0) -> 4136.42 | G54: =IFERROR('Data Sheet'!F63,0) -> 3256.46 | H54: =IFERROR('Data Sheet'!G63,0) -> 4011.29 | I54: =IFERROR('Data Sheet'!H63,0) -> 3225.54 | J54: =IFERROR('Data Sheet'!I63,0) -> 3003.3 | ... L54: =IFERROR('Data Sheet'!K63,0) -> 1090.91
B55: Investments | C55: =IFERROR('Data Sheet'!B64,0) -> 11747.59 | D55: =IFERROR('Data Sheet'!C64,0) -> 17581.38 | E55: =IFERROR('Data Sheet'!D64,0) -> 22052.86 | F55: =IFERROR('Data Sheet'!E64,0) -> 25043.49 | G55: =IFERROR('Data Sheet'!F64,0) -> 28663.35 | H55: =IFERROR('Data Sheet'!G64,0) -> 24870.87 | I55: =IFERROR('Data Sheet'!H64,0) -> 24841.01 | J55: =IFERROR('Data Sheet'!I64,0) -> 29415.02 | ... L55: =IFERROR('Data Sheet'!K64,0) -> 34719.82
B56: Other Assets | C56: =IFERROR('Data Sheet'!B65-SUM('Data Sheet'!B67:B69),0) -> 5194.82 | D56: =IFERROR('Data Sheet'!C65-SUM('Data Sheet'!C67:C69),0) -> 5135.78 | E56: =IFERROR('Data Sheet'!D65-SUM('Data Sheet'!D67:D69),0) -> 7078.75 | F56: =IFERROR('Data Sheet'!E65-SUM('Data Sheet'!E67:E69),0) -> 7138.07 | G56: =IFERROR('Data Sheet'!F65-SUM('Data Sheet'!F67:F69),0) -> 4958.45 | H56: =IFERROR('Data Sheet'!G65-SUM('Data Sheet'!G67:G69),0) -> 4022.24 | I56: =IFERROR('Data Sheet'!H65-SUM('Data Sheet'!H67:H69),0) -> 6917.41 | J56: =IFERROR('Data Sheet'!I65-SUM('Data Sheet'!I67:I69),0) -> 7953.85 | ... L56: =IFERROR('Data Sheet'!K65-SUM('Data Sheet'!K67:K69),0) -> 5867.53
B57: Total Non Current Assests | C57: =IFERROR(SUM(C53:C56),0) -> 34608.76 | D57: =IFERROR(SUM(D53:D56),0) -> 42340.53 | E57: =IFERROR(SUM(E53:E56),0) -> 51163.9 | F57: =IFERROR(SUM(F53:F56),0) -> 55692.17 | G57: =IFERROR(SUM(G53:G56),0) -> 58591.6 | H57: =IFERROR(SUM(H53:H56),0) -> 56202.88 | I57: =IFERROR(SUM(I53:I56),0) -> 59215.55 | J57: =IFERROR(SUM(J53:J56),0) -> 66223.44 | ... L57: =IFERROR(SUM(L53:L56),0) -> 63633.11
...

Sheet Data>

Sheet Data Sheet
A1: COMPANY NAME | B1: ITC LTD | E1: =IF(B2<>B3, "A NEW VERSION OF THE WORKSHEET IS AVAILABLE", "")
A2: LATEST VERSION | B2: 2.1 | E2: PLEASE DO NOT MAKE ANY CHANGES TO THIS SHEET
A3: CURRENT VERSION | B3: 2.1
A5: META
A6: Number of shares | B6: =IF(B9>0, B9/B8, 0) -> 1252.9468
A7: Face Value | B7: 1
A8: Current Price | B8: 293.7
A9: Market Capitalization | B9: 367990.48
A15: PROFIT & LOSS
A16: Report Date | B16: 42460 | C16: 42825 | D16: 43190 | E16: 43555 | F16: 43921 | G16: 44286 | H16: 44651 | I16: 45016 | J16: 45382 | K16: 45747
A17: Sales | B17: 39192.1 | C17: 42767.6 | D17: 43448.94 | E17: 48339.58 | F17: 49387.7 | G17: 49257.45 | H17: 60644.54 | I17: 70919.03 | J17: 67931.94 | K17: 75323.34
A18: Raw Material Cost | B18: 13763.88 | C18: 15456.59 | D18: 14827.72 | E18: 17623.52 | F18: 18048.6 | G18: 20776.71 | H18: 27071.07 | I18: 29364.36 | J18: 27348.57 | K18: 32704.37
A19: Change in Inventory | B19: 195.38 | C19: -592.57 | D19: -1027.76 | E19: 203.19 | F19: 703.13 | G19: 645.27 | H19: 686 | I19: 358.59 | J19: 367.77 | K19: 725.65
A20: Power and Fuel | B20: 571.88 | C20: 584.33 | D20: 653.5 | E20: 746.73 | F20: 780.85 | G20: 699.56 | H20: 889.77 | I20: 1232.34 | J20: 952.9 | K20: 975.35
A21: Other Mfr. Exp | B21: 1581.59 | C21: 1683.9 | D21: 1697.62 | E21: 1871.01 | F21: 1908.29 | G21: 1587.18 | H21: 1887.67 | I21: 2327.8 | J21: 2183.76 | K21: 2345.36
A22: Employee Cost | B22: 3440.97 | C22: 3631.73 | D22: 3760.9 | E22: 4177.88 | F22: 4295.79 | G22: 4463.33 | H22: 4890.55 | I22: 5736.22 | J22: 5548.53 | K22: 6169.78
A23: Selling and admin | B23: 4261.78 | C23: 4179.74 | D23: 3954.87 | E23: 4546.39 | F23: 4488.63 | G23: 4236.77 | H23: 4858.38 | I23: 5604.08 | J23: 5312.45 | K23: 5793.29
A24: Other Expenses | B24: 1235.89 | C24: 1169.23 | D24: 1005.98 | E24: 1039.85 | F24: 1225.13 | G24: 1074.39 | H24: 1109.95 | I24: 1308.56 | J24: 1765.97 | K24: 2221.39
A25: Other Income | B25: 1483.11 | C25: 1758.63 | D25: 2239.81 | E25: 2080.44 | F25: 2417.32 | G25: 2576.95 | H25: 1909.72 | I25: 2097.64 | J25: 3330.45 | K25: 17794.88
A26: Depreciation | B26: 1077.4 | C26: 1152.79 | D26: 1236.28 | E26: 1396.61 | F26: 1644.91 | G26: 1645.59 | H26: 1732.41 | I26: 1809.01 | J26: 1518.05 | K26: 1646.32
A27: Interest | B27: 78.13 | C27: 49.03 | D27: 115.01 | E27: 71.4 | F27: 81.38 | G27: 57.97 | H27: 59.99 | I27: 77.77 | J27: 39.11 | K27: 45.06
... A31: Dividend Amount | B31: 6840.12 | C31: 5770.02 | D31: 6285.21 | E31: 7048.7 | F31: 12476.58 | G31: 13231.96 | H31: 14171.8 | I31: 19263.4 | J31: 17166.46 | K31: 17957.73
A40: Quarters
A41: Report Date | B41: 45199 | C41: 45291 | D41: 45382 | E41: 45473 | F41: 45565 | G41: 45657 | H41: 45747 | I41: 45838 | J41: 45930 | K41: 46022
A42: Sales | B42: 17774.47 | C42: 17195.24 | D42: 17037.8 | E42: 17777.81 | F42: 19990.36 | G42: 18790.17 | H42: 18765 | I42: 21494.79 | J42: 19501.63 | K42: 20047.3
A43: Expenses | B43: 11320.23 | C43: 10985.01 | D43: 10735.73 | E43: 11232.97 | F43: 13438.28 | G43: 12428.27 | H43: 12245.61 | I43: 14678.32 | J43: 12806.94 | K43: 13164.78
A44: Other Income | B44: 673.5 | C44: 820.26 | D44: 868 | E44: 771.13 | F44: 690.31 | G44: 803.4 | H44: 15391.28 | I44: 750.97 | J44: 738.84 | K44: 321.85
A45: Depreciation | B45: 453.04 | C45: 384.04 | D45: 385.09 | E45: 403.13 | F45: 416.18 | G45: 415.98 | H45: 411.03 | I45: 422.96 | J45: 434.8 | K45: 430.82
A46: Interest | B46: 9.87 | C46: 11.94 | D46: 10.72 | E46: 9.6 | F46: 14.73 | G46: 9.82 | H46: 10.91 | I46: 16.47 | J46: 20.05 | K46: 19.47
A47: Profit before tax | B47: 6664.83 | C47: 6634.51 | D47: 6774.26 | E47: 6903.24 | F47: 6811.48 | G47: 6739.5 | H47: 21488.73 | I47: 7128.01 | J47: 6978.68 | K47: 6754.08
A48: Tax | B48: 1700.31 | C48: 1227.99 | D48: 1583.55 | E48: 1726.25 | F48: 1757.05 | G48: 1726.32 | H48: 1680.85 | I48: 1784.6 | J48: 1792.13 | K48: 1735.63
A49: Net profit | B49: 4898.07 | C49: 5335.23 | D49: 5120.55 | E49: 5091.59 | F49: 4992.87 | G49: 4934.8 | H49: 19727.37 | I49: 5244.2 | J49: 5126.11 | K49: 4931.19
A50: Operating Profit | B50: 6454.24 | C50: 6210.23 | D50: 6302.07 | E50: 6544.84 | F50: 6552.08 | G50: 6361.9 | H50: 6519.39 | I50: 6816.47 | J50: 6694.69 | K50: 6882.52
A55: BALANCE SHEET
A56: Report Date | B56: 42460 | C56: 42825 | D56: 43190 | E56: 43555 | F56: 43921 | G56: 44286 | H56: 44651 | I56: 45016 | J56: 45382 | K56: 45747
A57: Equity Share Capital | B57: 804.72 | C57: 1214.74 | D57: 1220.43 | E57: 1225.86 | F57: 1229.22 | G57: 1230.88 | H57: 1232.33 | I57: 1242.8 | J57: 1248.47 | K57: 1251.41
A58: Reserves | B58: 41874.8 | C58: 45198.19 | D58: 51289.68 | E58: 57915.01 | F58: 64044.04 | G58: 59116.46 | H58: 61223.24 | I58: 67912.46 | J58: 73258.53 | K58: 68778.64
A59: Borrowings | B59: 83.78 | C59: 45.72 | D59: 35.92 | E59: 13.44 | F59: 277.45 | G59: 270.83 | H59: 249.44 | I59: 306.04 | J59: 303.43 | K59: 284.54
A60: Other Liabilities | B60: 8888.04 | C60: 9439.67 | D60: 11694.85 | E60: 12584.73 | F60: 11760.04 | G60: 13142.59 | H60: 14491.01 | I60: 16369.66 | J60: 16943.54 | K60: 17688.11
A61: Total | B61: 51651.34 | C61: 55898.32 | D61: 64240.88 | E61: 71739.04 | F61: 77310.75 | G61: 73760.76 | H61: 77196.02 | I61: 85830.96 | J61: 91753.97 | K61: 88002.7
...

Sheet Cash Flow Data
C2: 41699 | D2: 42064 | E2: 42430 | F2: 42795 | G2: 43160 | H2: 43525 | I2: 43891 | J2: 44256 | K2: 44621 | L2: 44986 | M2: 45352 | N2: 45717
B3: Cash from Operating Activity - | C3: 7344 | D3: 9843 | E3: 9799 | F3: 10627 | G3: 13169 | H3: 12583 | I3: 14690 | J3: 12527 | K3: 15776 | L3: 18878 | M3: 17179 | N3: 17627
B4: Profit from operations | C4: 13172 | D4: 14261 | E4: 15154 | F4: 16075 | G4: 17433 | H4: 18862 | I4: 19416 | J4: 17326 | K4: 20857 | L4: 26052 | M4: 26635 | N4: 26719
B5: Receivables | C5: -1546 | D5: 558 | E5: -207 | F5: -870 | G5: -964 | H5: -755 | I5: 1411 | J5: -66 | K5: -732 | L5: -884 | M5: -934 | N5: -1023
B6: Inventory | C6: -755 | D6: -505 | E6: -693 | F6: 593 | G6: 602 | H6: -359 | I6: -508 | J6: -1460 | K6: -466 | L6: -1098 | M6: -2545 | N6: -2975
B7: Payables | C7: 456 | D7: -23 | E7: 622 | F7: 321 | G7: 2098 | H7: 639 | I7: -607 | J7: 1112 | K7: 1099 | L7: 1058 | M7: 141 | N7: 1256
B8: Working capital changes | C8: -1844 | D8: 31 | E8: -277 | F8: 44 | G8: 1736 | H8: -476 | I8: 296 | J8: -413 | K8: -100 | L8: -924 | M8: -3337 | N8: -2742
B9: Direct taxes | C9: -3984 | D9: -4449 | E9: -5078 | F9: -5492 | G9: -6000 | H9: -5803 | I9: -5023 | J9: -4387 | K9: -4982 | L9: -6250 | M9: -6120 | N9: -6350
B10: Cash from Investing Activity - | C10: -3254 | D10: -5275 | E10: -3921 | F10: -3251 | G10: -7114 | H10: -5546 | I10: -6174 | J10: 5740 | K10: -2238 | L10: -5732 | M10: 1563 | N10: -564
B11: Fixed assets purchased | C11: -2887 | D11: -3300 | E11: -2348 | F11: -3122 | G11: -2878 | H11: -3169 | I11: -2441 | J11: -1837 | K11: -2142 | L11: -2743 | M11: -3563 | N11: -2279
B12: Fixed assets sold | C12: 38 | D12: 9 | E12: 8 | F12: 50 | G12: 80 | H12: 28 | I12: 27 | J12: 3 | K12: 133 | L12: 49 | M12: 107 | N12: 175
B13: Investments purchased | C13: -94242 | D13: -98742 | E13: -154081 | F13: -85683 | G13: -98330 | H13: -94187 | I13: -79835 | J13: -57553 | K13: -69776 | L13: -80932 | M13: -75107 | N13: -66373
B14: Investments sold | C14: 93293 | D14: 99658 | E14: 150651 | F14: 81034 | G14: 95017 | H14: 92454 | I14: 75835 | J14: 62797 | K14: 70992 | L14: 77230 | M14: 77830 | N14: 67311
... B31: CFO/OP | C31: 0.87 | D31: 1 | E31: 1.02 | F31: 1.04 | G31: 1.16 | H31: 0.99 | I31: 1.02 | J31: 0.99 | K31: 1.01 | L31: 0.98 | M31: 0.92 | N31: 0.93
